<?xml version="1.0" ?>
<sdf version='1.6'>
  <world name='default'>
    <model name='ground_plane'>
      <static>1</static>
      <link name='link'>
        <collision name='collision'>
          <geometry>
            <plane>
              <normal>0 0 1</normal>
              <size>100 100</size>
            </plane>
          </geometry>
          <surface>
            <friction>
              <ode>
                <mu>100</mu>
                <mu2>50</mu2>
              </ode>
              <torsional>
                <ode/>
              </torsional>
            </friction>
            <contact>
              <ode/>
            </contact>
            <bounce/>
          </surface>
          <max_contacts>10</max_contacts>
        </collision>
        <visual name='visual'>
          <cast_shadows>0</cast_shadows>
          <geometry>
            <plane>
              <normal>0 0 1</normal>
              <size>100 100</size>
            </plane>
          </geometry>
          <material>
            <script>
              <uri>file://media/materials/scripts/gazebo.material</uri>
              <name>Gazebo/Grey</name>
            </script>
          </material>
        </visual>
        <self_collide>0</self_collide>
        <kinematic>0</kinematic>
      </link>
    </model>
    <light name='sun' type='directional'>
      <cast_shadows>1</cast_shadows>
      <pose frame=''>0 0 10 0 -0 0</pose>
      <diffuse>0.8 0.8 0.8 1</diffuse>
      <specular>0.2 0.2 0.2 1</specular>
      <attenuation>
        <range>1000</range>
        <constant>0.9</constant>
        <linear>0.01</linear>
        <quadratic>0.001</quadratic>
      </attenuation>
      <direction>-0.5 0.1 -0.9</direction>
    </light>
    <gui fullscreen='0'>
      <camera name='user_camera'>
        <pose frame=''>2.7132 7.76649 1.58076 -0 0.025848 -1.93074</pose>
        <view_controller>orbit</view_controller>
        <projection_type>perspective</projection_type>
      </camera>
    </gui>
    <gravity>0 0 -9.8</gravity>
    <magnetic_field>6e-06 2.3e-05 -4.2e-05</magnetic_field>
    <atmosphere type='adiabatic'/>
    <physics name='default_physics' default='0' type='ode'>
      <max_step_size>0.001</max_step_size>
      <real_time_factor>1</real_time_factor>
      <real_time_update_rate>1000</real_time_update_rate>
    </physics>
    <scene>
      <ambient>0.4 0.4 0.4 1</ambient>
      <background>0.7 0.7 0.7 1</background>
      <shadows>1</shadows>
    </scene>
    <spherical_coordinates>
      <surface_model>EARTH_WGS84</surface_model>
      <latitude_deg>0</latitude_deg>
      <longitude_deg>0</longitude_deg>
      <elevation>0</elevation>
      <heading_deg>0</heading_deg>
    </spherical_coordinates>
    <model name='rrbot'>
      <link name='base_link'>
        <pose frame=''>0 0 0 0 -0 0</pose>
        <inertial>
          <pose frame=''>-0.279794 0 -0.149211 0 -0 0</pose>
          <mass>85</mass>
          <inertia>
            <ixx>5.4005</ixx>
            <ixy>0</ixy>
            <ixz>1.64962</ixz>
            <iyy>36.1465</iyy>
            <iyz>0</iyz>
            <izz>38.5473</izz>
          </inertia>
        </inertial>
        <collision name='base_link_collision'>
          <pose frame=''>0 0 0 0 -0 0</pose>
          <geometry>
            <box>
              <size>0.1 0.1 0.1</size>
            </box>
          </geometry>
          <surface>
            <contact>
              <ode/>
            </contact>
            <friction>
              <ode/>
              <torsional>
                <ode/>
              </torsional>
            </friction>
            <bounce/>
          </surface>
          <max_contacts>10</max_contacts>
        </collision>
        <collision name='base_link_fixed_joint_lump__car_body_collision_1'>
          <pose frame=''>0 0 -0.197765 0 -0 0</pose>
          <geometry>
            <box>
              <size>1.94 0.76 0.29553</size>
            </box>
          </geometry>
          <surface>
            <contact>
              <ode/>
            </contact>
            <friction>
              <ode/>
              <torsional>
                <ode/>
              </torsional>
            </friction>
            <bounce/>
          </surface>
          <max_contacts>10</max_contacts>
        </collision>
        <collision name='base_link_fixed_joint_lump__motor_link_collision_2'>
          <pose frame=''>-0.6795 0 -0.027235 0 -0 0</pose>
          <geometry>
            <box>
              <size>0.25 0.25 0.25</size>
            </box>
          </geometry>
          <surface>
            <contact>
              <ode/>
            </contact>
            <friction>
              <ode/>
              <torsional>
                <ode/>
              </torsional>
            </friction>
            <bounce/>
          </surface>
          <max_contacts>10</max_contacts>
        </collision>
        <collision name='base_link_fixed_joint_lump__rear_link_collision_3'>
          <pose frame=''>-0.6795 0 -0.472765 0 -0 0</pose>
          <geometry>
            <box>
              <size>0.1 0.1 0.25447</size>
            </box>
          </geometry>
          <surface>
            <contact>
              <ode/>
            </contact>
            <friction>
              <ode/>
              <torsional>
                <ode/>
              </torsional>
            </friction>
            <bounce/>
          </surface>
          <max_contacts>10</max_contacts>
        </collision>
        <visual name='base_link_visual'>
          <pose frame=''>0 0 0 0 -0 0</pose>
          <geometry>
            <box>
              <size>0.1 0.1 0.1</size>
            </box>
          </geometry>
          <material>
            <script>
              <name>Gazebo/White</name>
              <uri>file://media/materials/scripts/gazebo.material</uri>
            </script>
          </material>
        </visual>
        <visual name='base_link_fixed_joint_lump__car_body_visual_1'>
          <pose frame=''>0 0 -0.197765 0 -0 0</pose>
          <geometry>
            <box>
              <size>1.94 0.76 0.29553</size>
            </box>
          </geometry>
          <material>
            <script>
              <name>Gazebo/Grey</name>
              <uri>file://media/materials/scripts/gazebo.material</uri>
            </script>
          </material>
        </visual>
        <visual name='base_link_fixed_joint_lump__motor_link_visual_2'>
          <pose frame=''>-0.6795 0 -0.027235 0 -0 0</pose>
          <geometry>
            <box>
              <size>0.25 0.25 0.25</size>
            </box>
          </geometry>
          <material>
            <script>
              <name>Gazebo/Grey</name>
              <uri>file://media/materials/scripts/gazebo.material</uri>
            </script>
          </material>
        </visual>
        <visual name='base_link_fixed_joint_lump__rear_link_visual_3'>
          <pose frame=''>-0.6795 0 -0.472765 0 -0 0</pose>
          <geometry>
            <box>
              <size>0.1 0.1 0.25447</size>
            </box>
          </geometry>
          <material>
            <script>
              <name>Gazebo/Red</name>
              <uri>file://media/materials/scripts/gazebo.material</uri>
            </script>
          </material>
        </visual>
        <velocity_decay/>
        <velocity_decay/>
        <velocity_decay/>
        <gravity>1</gravity>
        <velocity_decay/>
        <self_collide>0</self_collide>
        <kinematic>0</kinematic>
      </link>
      <link name='front_link'>
        <pose frame=''>0.6795 0 -0.34553 0 -0 0</pose>
        <inertial>
          <pose frame=''>0 0 0.127235 0 -0 0</pose>
          <mass>5</mass>
          <inertia>
            <ixx>0.1</ixx>
            <ixy>0</ixy>
            <ixz>0</ixz>
            <iyy>0.1</iyy>
            <iyz>0</iyz>
            <izz>0.1</izz>
          </inertia>
        </inertial>
        <collision name='front_link_collision'>
          <pose frame=''>0 0 0.127235 0 -0 0</pose>
          <geometry>
            <box>
              <size>0.1 0.1 0.25447</size>
            </box>
          </geometry>
          <surface>
            <contact>
              <ode/>
            </contact>
            <friction>
              <ode/>
              <torsional>
                <ode/>
              </torsional>
            </friction>
            <bounce/>
          </surface>
          <max_contacts>10</max_contacts>
        </collision>
        <visual name='front_link_visual'>
          <pose frame=''>0 0 -0.127235 0 -0 0</pose>
          <geometry>
            <box>
              <size>0.1 0.1 0.25447</size>
            </box>
          </geometry>
          <material>
            <script>
              <name>Gazebo/Red</name>
              <uri>file://media/materials/scripts/gazebo.material</uri>
            </script>
          </material>
        </visual>
        <gravity>1</gravity>
        <velocity_decay/>
        <self_collide>0</self_collide>
        <kinematic>0</kinematic>
      </link>
      <joint name='front_joint' type='revolute'>
        <child>front_link</child>
        <parent>base_link</parent>
        <axis>
          <xyz>0 0 1</xyz>
          <limit>
            <lower>-0.785398</lower>
            <upper>0.785398</upper>
            <effort>100</effort>
            <velocity>2</velocity>
          </limit>
          <dynamics>
            <damping>0.7</damping>
            <friction>0</friction>
            <spring_reference>0</spring_reference>
            <spring_stiffness>0</spring_stiffness>
          </dynamics>
          <use_parent_model_frame>1</use_parent_model_frame>
        </axis>
      </joint>
      <link name='front_axel_link'>
        <pose frame=''>0.6795 0 -0.6 0 -0 0</pose>
        <inertial>
          <pose frame=''>0 0 0 0 -0 0</pose>
          <mass>7</mass>
          <inertia>
            <ixx>0.0425484</ixx>
            <ixy>0</ixy>
            <ixz>0</ixz>
            <iyy>0.03</iyy>
            <iyz>0</iyz>
            <izz>0.0425484</izz>
          </inertia>
        </inertial>
        <collision name='front_axel_link_collision'>
          <pose frame=''>0 0 0 0 -0 0</pose>
          <geometry>
            <box>
              <size>0.05 0.1 0.05</size>
            </box>
          </geometry>
          <surface>
            <contact>
              <ode/>
            </contact>
            <friction>
              <ode/>
              <torsional>
                <ode/>
              </torsional>
            </friction>
            <bounce/>
          </surface>
          <max_contacts>10</max_contacts>
        </collision>
        <collision name='front_axel_link_fixed_joint_lump__front_left_wheel_link_collision_1'>
          <pose frame=''>0 -0.07921 0 1.5708 -0 0</pose>
          <geometry>
            <cylinder>
              <length>0.05842</length>
              <radius>0.20447</radius>
            </cylinder>
          </geometry>
          <surface>
            <contact>
              <ode/>
            </contact>
            <friction>
              <ode/>
              <torsional>
                <ode/>
              </torsional>
            </friction>
            <bounce/>
          </surface>
          <max_contacts>10</max_contacts>
        </collision>
        <collision name='front_axel_link_fixed_joint_lump__front_right_wheel_link_collision_2'>
          <pose frame=''>0 0.07921 0 1.5708 -0 0</pose>
          <geometry>
            <cylinder>
              <length>0.05842</length>
              <radius>0.20447</radius>
            </cylinder>
          </geometry>
          <surface>
            <contact>
              <ode/>
            </contact>
            <friction>
              <ode/>
              <torsional>
                <ode/>
              </torsional>
            </friction>
            <bounce/>
          </surface>
          <max_contacts>10</max_contacts>
        </collision>
        <visual name='front_axel_link_visual'>
          <pose frame=''>0 0 0 0 -0 0</pose>
          <geometry>
            <box>
              <size>0.05 0.1 0.05</size>
            </box>
          </geometry>
          <material>
            <script>
              <name>Gazebo/Green</name>
              <uri>file://media/materials/scripts/gazebo.material</uri>
            </script>
          </material>
        </visual>
        <visual name='front_axel_link_fixed_joint_lump__front_left_wheel_link_visual_1'>
          <pose frame=''>0 -0.07921 0 1.5708 -0 0</pose>
          <geometry>
            <cylinder>
              <length>0.05842</length>
              <radius>0.20447</radius>
            </cylinder>
          </geometry>
          <material>
            <script>
              <name>Gazebo/Grey</name>
              <uri>file://media/materials/scripts/gazebo.material</uri>
            </script>
          </material>
        </visual>
        <visual name='front_axel_link_fixed_joint_lump__front_right_wheel_link_visual_2'>
          <pose frame=''>0 0.07921 0 1.5708 -0 0</pose>
          <geometry>
            <cylinder>
              <length>0.05842</length>
              <radius>0.20447</radius>
            </cylinder>
          </geometry>
          <material>
            <script>
              <name>Gazebo/Grey</name>
              <uri>file://media/materials/scripts/gazebo.material</uri>
            </script>
          </material>
        </visual>
        <velocity_decay/>
        <velocity_decay/>
        <gravity>1</gravity>
        <velocity_decay/>
        <self_collide>0</self_collide>
        <kinematic>0</kinematic>
      </link>
      <joint name='front_axel_joint' type='revolute'>
        <child>front_axel_link</child>
        <parent>front_link</parent>
        <axis>
          <xyz>0 1 0</xyz>
          <limit>
            <lower>-1e+16</lower>
            <upper>1e+16</upper>
          </limit>
          <dynamics>
            <damping>0.1</damping>
            <friction>0</friction>
            <spring_reference>0</spring_reference>
            <spring_stiffness>0</spring_stiffness>
          </dynamics>
          <use_parent_model_frame>1</use_parent_model_frame>
        </axis>
      </joint>
      <link name='rear_axel_link'>
        <pose frame=''>-0.6795 0 -0.6 0 -0 0</pose>
        <inertial>
          <pose frame=''>0 0.087678 0 0 -0 0</pose>
          <mass>8.5</mass>
          <inertia>
            <ixx>0.828632</ixx>
            <ixy>0</ixy>
            <ixz>0</ixz>
            <iyy>0.03</iyy>
            <iyz>0</iyz>
            <izz>0.828632</izz>
          </inertia>
        </inertial>
        <collision name='rear_axel_link_collision'>
          <pose frame=''>0 0 0 0 -0 0</pose>
          <geometry>
            <box>
              <size>0.05 0.87684 0.05</size>
            </box>
          </geometry>
          <surface>
            <contact>
              <ode/>
            </contact>
            <friction>
              <ode/>
              <torsional>
                <ode/>
              </torsional>
            </friction>
            <bounce/>
          </surface>
          <max_contacts>10</max_contacts>
        </collision>
        <collision name='rear_axel_link_fixed_joint_lump__rear_left_wheel_link_collision_1'>
          <pose frame=''>0 -0.49684 0 1.5708 -0 0</pose>
          <geometry>
            <cylinder>
              <length>0.11684</length>
              <radius>0.20447</radius>
            </cylinder>
          </geometry>
          <surface>
            <contact>
              <ode/>
            </contact>
            <friction>
              <ode/>
              <torsional>
                <ode/>
              </torsional>
            </friction>
            <bounce/>
          </surface>
          <max_contacts>10</max_contacts>
        </collision>
        <collision name='rear_axel_link_fixed_joint_lump__left_spin_link_collision_2'>
          <pose frame=''>0 -0.55526 0 0 -0 0</pose>
          <geometry>
            <box>
              <size>0.306705 0.01 0.05</size>
            </box>
          </geometry>
          <surface>
            <contact>
              <ode/>
            </contact>
            <friction>
              <ode/>
              <torsional>
                <ode/>
              </torsional>
            </friction>
            <bounce/>
          </surface>
          <max_contacts>10</max_contacts>
        </collision>
        <collision name='rear_axel_link_fixed_joint_lump__rear_right_wheel_link_collision_3'>
          <pose frame=''>0 0.49684 0 1.5708 -0 0</pose>
          <geometry>
            <cylinder>
              <length>0.11684</length>
              <radius>0.20447</radius>
            </cylinder>
          </geometry>
          <surface>
            <contact>
              <ode/>
            </contact>
            <friction>
              <ode/>
              <torsional>
                <ode/>
              </torsional>
            </friction>
            <bounce/>
          </surface>
          <max_contacts>10</max_contacts>
        </collision>
        <collision name='rear_axel_link_fixed_joint_lump__right_spin_link_collision_4'>
          <pose frame=''>0 0.55526 0 0 -0 0</pose>
          <geometry>
            <box>
              <size>0.306705 0.01 0.05</size>
            </box>
          </geometry>
          <surface>
            <contact>
              <ode/>
            </contact>
            <friction>
              <ode/>
              <torsional>
                <ode/>
              </torsional>
            </friction>
            <bounce/>
          </surface>
          <max_contacts>10</max_contacts>
        </collision>
        <visual name='rear_axel_link_visual'>
          <pose frame=''>0 0 0 0 -0 0</pose>
          <geometry>
            <box>
              <size>0.05 0.87684 0.05</size>
            </box>
          </geometry>
          <material>
            <script>
              <name>Gazebo/Green</name>
              <uri>file://media/materials/scripts/gazebo.material</uri>
            </script>
          </material>
        </visual>
        <visual name='rear_axel_link_fixed_joint_lump__rear_left_wheel_link_visual_1'>
          <pose frame=''>0 -0.49684 0 1.5708 -0 0</pose>
          <geometry>
            <cylinder>
              <length>0.11684</length>
              <radius>0.20447</radius>
            </cylinder>
          </geometry>
          <material>
            <script>
              <name>Gazebo/Grey</name>
              <uri>file://media/materials/scripts/gazebo.material</uri>
            </script>
          </material>
        </visual>
        <visual name='rear_axel_link_fixed_joint_lump__left_spin_link_visual_2'>
          <pose frame=''>0 -0.55526 0 0 -0 0</pose>
          <geometry>
            <box>
              <size>0.306705 0.01 0.05</size>
            </box>
          </geometry>
          <material>
            <script>
              <name>Gazebo/Red</name>
              <uri>file://media/materials/scripts/gazebo.material</uri>
            </script>
          </material>
        </visual>
        <visual name='rear_axel_link_fixed_joint_lump__rear_right_wheel_link_visual_3'>
          <pose frame=''>0 0.49684 0 1.5708 -0 0</pose>
          <geometry>
            <cylinder>
              <length>0.11684</length>
              <radius>0.20447</radius>
            </cylinder>
          </geometry>
          <material>
            <script>
              <name>Gazebo/Grey</name>
              <uri>file://media/materials/scripts/gazebo.material</uri>
            </script>
          </material>
        </visual>
        <visual name='rear_axel_link_fixed_joint_lump__right_spin_link_visual_4'>
          <pose frame=''>0 0.55526 0 0 -0 0</pose>
          <geometry>
            <box>
              <size>0.306705 0.01 0.05</size>
            </box>
          </geometry>
          <material>
            <script>
              <name>Gazebo/Green</name>
              <uri>file://media/materials/scripts/gazebo.material</uri>
            </script>
          </material>
        </visual>
        <velocity_decay/>
        <velocity_decay/>
        <velocity_decay/>
        <velocity_decay/>
        <gravity>1</gravity>
        <velocity_decay/>
        <self_collide>0</self_collide>
        <kinematic>0</kinematic>
      </link>
      <joint name='rear_axel_joint' type='revolute'>
        <child>rear_axel_link</child>
        <parent>base_link</parent>
        <axis>
          <xyz>0 1 0</xyz>
          <limit>
            <lower>-1e+16</lower>
            <upper>1e+16</upper>
          </limit>
          <dynamics>
            <damping>5</damping>
            <friction>0</friction>
            <spring_reference>0</spring_reference>
            <spring_stiffness>0</spring_stiffness>
          </dynamics>
          <use_parent_model_frame>1</use_parent_model_frame>
        </axis>
      </joint>
      <static>0</static>
      <plugin name='gazebo_ros_control' filename='libgazebo_ros_control.so'>
        <robotNamespace>/car_test</robotNamespace>
        <robotSimType>gazebo_ros_control/DefaultRobotHWSim</robotSimType>
      </plugin>
      <pose frame=''>0 0 0 0 -0 0</pose>
    </model>
    <model name='unit_box'>
      <pose frame=''>0.019741 -2.5061 0.5 0 -0 0</pose>
      <link name='link'>
        <inertial>
          <mass>1</mass>
          <inertia>
            <ixx>0.166667</ixx>
            <ixy>0</ixy>
            <ixz>0</ixz>
            <iyy>0.166667</iyy>
            <iyz>0</iyz>
            <izz>0.166667</izz>
          </inertia>
        </inertial>
        <collision name='collision'>
          <geometry>
            <box>
              <size>1 1 1</size>
            </box>
          </geometry>
          <max_contacts>10</max_contacts>
          <surface>
            <contact>
              <ode/>
            </contact>
            <bounce/>
            <friction>
              <torsional>
                <ode/>
              </torsional>
              <ode/>
            </friction>
          </surface>
        </collision>
        <visual name='visual'>
          <geometry>
            <box>
              <size>1 1 1</size>
            </box>
          </geometry>
          <material>
            <script>
              <name>Gazebo/Grey</name>
              <uri>file://media/materials/scripts/gazebo.material</uri>
            </script>
          </material>
        </visual>
        <self_collide>0</self_collide>
        <kinematic>0</kinematic>
      </link>
    </model>
    <state world_name='default'>
      <sim_time>77 228000000</sim_time>
      <real_time>77 811970247</real_time>
      <wall_time>1548957844 489014553</wall_time>
      <iterations>77228</iterations>
      <model name='ground_plane'>
        <pose frame=''>0 0 0 0 -0 0</pose>
        <scale>1 1 1</scale>
        <link name='link'>
          <pose frame=''>0 0 0 0 -0 0</pose>
          <velocity>0 0 0 0 -0 0</velocity>
          <acceleration>0 0 0 0 -0 0</acceleration>
          <wrench>0 0 0 0 -0 0</wrench>
        </link>
      </model>
      <model name='rrbot'>
        <pose frame=''>0.007627 -0.003718 0.80447 4e-06 -3e-06 -0.009225</pose>
        <scale>1 1 1</scale>
        <link name='base_link'>
          <pose frame=''>0.007627 -0.003718 0.80447 4e-06 -3e-06 -0.009225</pose>
          <velocity>-0.000169 -0.003454 0.000647 0.006964 -0.000926 0.001965</velocity>
          <acceleration>0.053422 -5.77983 1.7731 -0.639915 1.01127 -1.93655</acceleration>
          <wrench>4.54086 -491.286 150.713 0 -0 0</wrench>
        </link>
        <link name='front_axel_link'>
          <pose frame=''>0.6871 -0.009983 0.204472 1e-05 0.228803 0.031793</pose>
          <velocity>0.000479 0.001494 0.00125 -0.00717 0.002193 -0.000315</velocity>
          <acceleration>-0.304386 2.51196 0.640024 0.425151 -1.30543 0.160982</acceleration>
          <wrench>-2.1307 17.5837 4.48017 0 -0 0</wrench>
        </link>
        <link name='front_link'>
          <pose frame=''>0.687099 -0.009985 0.458942 9e-06 -4e-06 0.031791</pose>
          <velocity>0.00019 8.9e-05 0.001243 0.003015 -0.001339 -0.000415</velocity>
          <acceleration>-0.014317 -0.242442 0.627581 -1.79818 0.608699 0.088255</acceleration>
          <wrench>-0.071583 -1.21221 3.1379 0 -0 0</wrench>
        </link>
        <link name='rear_axel_link'>
          <pose frame=''>-0.671842 0.002554 0.204469 3e-06 -0.203843 -0.009225</pose>
          <velocity>0.000365 -0.001519 0.000483 0.007389 -0.002674 0.001798</velocity>
          <acceleration>-0.842028 -2.66087 3.70204 -2.64034 1.11866 1.23337</acceleration>
          <wrench>-7.15724 -22.6174 31.4673 0 -0 0</wrench>
        </link>
      </model>
      <model name='unit_box'>
        <pose frame=''>0.018483 -2.5058 1.6109 0 -0 0.000604</pose>
        <scale>10 0.5 3</scale>
	<static>true</static>
        <link name='link'>
          <pose frame=''>0.018483 -2.5058 1.6109 0 -0 0.000604</pose>
          <velocity>0 0 0 0 -0 0</velocity>
          <acceleration>-6.8218 -4.03655 9.45626 2.37098 1.18644 -0.100164</acceleration>
          <wrench>-6.8218 -4.03655 9.45626 0 -0 0</wrench>
        </link>
      </model>
      <light name='sun'>
        <pose frame=''>0 0 10 0 -0 0</pose>
      </light>
    </state>
  </world>
</sdf>
