<?xml version="1.0" ?>
<!-- =================================================================================== -->
<!-- |    This document was autogenerated by xacro from taylor.xacro                   | -->
<!-- |    EDITING THIS FILE BY HAND IS NOT RECOMMENDED                                 | -->
<!-- =================================================================================== -->
<!-- Revolute-Revolute Manipulator -->
<robot name="taylor" xmlns:xacro="http://www.ros.org/wiki/xacro">
  <!-- ros_control plugin -->
  <gazebo>
    <plugin filename="libgazebo_ros_control.so" name="gazebo_ros_control">
      <robotNamespace>/car_test</robotNamespace>
      <robotSimType>gazebo_ros_control/DefaultRobotHWSim</robotSimType>
    </plugin>
  </gazebo>
  <!-- materials -->
  <gazebo reference="base_link">
    <material>Gazebo/White</material>
  </gazebo>
  <gazebo reference="car_body">
    <material>Gazebo/Grey</material>
  </gazebo>
  <gazebo reference="motor_link">
    <material>Gazebo/Grey</material>
  </gazebo>
  <gazebo reference="front_link">
    <material>Gazebo/Red</material>
  </gazebo>
  <gazebo reference="front_axel_link">
    <material>Gazebo/Green</material>
  </gazebo>
  <gazebo reference="rear_link">
    <material>Gazebo/Red</material>
  </gazebo>
  <gazebo reference="rear_axel_link">
    <material>Gazebo/Green</material>
  </gazebo>
  <gazebo reference="front_left_wheel_link">
    <material>Gazebo/Grey</material>
  </gazebo>
  <gazebo reference="front_right_wheel_link">
    <material>Gazebo/Grey</material>
  </gazebo>
  <gazebo reference="rear_left_wheel_link">
    <material>Gazebo/Grey</material>
  </gazebo>
  <gazebo reference="rear_right_wheel_link">
    <material>Gazebo/Grey</material>
  </gazebo>
  <gazebo reference="left_spin_link">
    <material>Gazebo/Red</material>
  </gazebo>
  <gazebo reference="right_spin_link">
    <material>Gazebo/Green</material>
  </gazebo>
  <!--
   <gazebo reference="sensor_laser">
    <sensor type="ray" name="lidar_sensor">
      <pose>0 0 0 0 0 0</pose>
      <visualize>true</visualize>
      <update_rate>20</update_rate>
      <ray>
        <scan>
          <horizontal>
            <samples>720</samples>
            <resolution>1</resolution>
            <min_angle>-1.570796</min_angle>
            <max_angle>1.570796</max_angle>
          </horizontal>
        </scan>
        <range>
          <min>0.20</min>
          <max>10.0</max>
          <resolution>0.01</resolution>
        </range>
        <noise>
          <type>gaussian</type>
          <mean>0.0</mean>
          <stddev>0.01</stddev>
        </noise>
      </ray>
      <plugin name="gazebo_ros_head_hokuyo_controller" filename="libgazebo_ros_laser.so">
        <topicName>/taylordunn/laserscan</topicName>
        <frameName>sensor_laser</frameName>
      </plugin>
    </sensor>
  </gazebo>
-->
  <material name="black">
    <color rgba="0.0 0.0 0.0 1.0"/>
  </material>
  <material name="blue">
    <color rgba="0.0 0.0 0.8 1.0"/>
  </material>
  <material name="green">
    <color rgba="0.0 0.8 0.0 1.0"/>
  </material>
  <material name="grey">
    <color rgba="0.2 0.2 0.2 1.0"/>
  </material>
  <material name="orange">
    <color rgba="1.0 0.423529411765 0.0392156862745 1.0"/>
  </material>
  <material name="brown">
    <color rgba="0.870588235294 0.811764705882 0.764705882353 1.0"/>
  </material>
  <material name="red">
    <color rgba="0.8 0.0 0.0 1.0"/>
  </material>
  <material name="white">
    <color rgba="1.0 1.0 1.0 1.0"/>
  </material>
  <!--_________________________________________ Body ______________________________________-->
  <link name="base_link">
    <visual>
      <origin rpy="0 0 0" xyz="0 0 0"/>
      <geometry>
        <box size="0.1 0.1 0.1"/>
      </geometry>
      <material name="white"/>
    </visual>
    <collision>
      <origin rpy="0 0 0" xyz="0 0 0"/>
      <geometry>
        <box size="0.1 0.1 0.1"/>
      </geometry>
    </collision>
  </link>
  <joint name="base_joint" type="fixed">
    <parent link="base_link"/>
    <child link="car_body"/>
    <origin xyz="0 0 -0.05"/>
  </joint>
  <link name="car_body">
    <inertial>
      <origin rpy="0 0 0" xyz="0 0 -0.147765"/>
      <mass value="50"/>
      <inertia ixx="2.77057492042" ixy="0.0" ixz="0.0" iyy="16.0455749204" iyz="0.0" izz="18.0883333333"/>
    </inertial>
    <visual>
      <origin rpy="0 0 0" xyz="0 0 -0.147765"/>
      <geometry>
        <box size="1.94 0.76 0.29553"/>
      </geometry>
      <material name="grey"/>
    </visual>
    <collision>
      <origin rpy="0 0 0" xyz="0 0 -0.147765"/>
      <geometry>
        <box size="1.94 0.76 0.29553"/>
      </geometry>
    </collision>
  </link>
  <joint name="motor_joint" type="fixed">
    <parent link="car_body"/>
    <child link="motor_link"/>
    <origin xyz="-0.6795 0.0 0.147765"/>
  </joint>
  <link name="motor_link">
    <inertial>
      <mass value="30"/>
      <origin rpy="0 0 0" xyz="0 0 -0.125"/>
      <inertia ixx="1.66234495225" ixy="0.0" ixz="0.0" iyy="9.62734495225" iyz="0.0" izz="10.853"/>
    </inertial>
    <visual>
      <origin rpy="0 0 0" xyz="0 0 -0.125"/>
      <geometry>
        <box size="0.25 0.25 0.25"/>
      </geometry>
      <material name="grey"/>
    </visual>
    <collision>
      <origin rpy="0 0 0" xyz="0 0 -0.125"/>
      <geometry>
        <box size="0.25 0.25 0.25"/>
      </geometry>
    </collision>
  </link>
  <!-- LiDAR -->
  <joint name="lidar_joint" type="fixed">
    <parent link="car_body"/>
    <child link="lidar_link"/>
    <origin xyz="0.9 0.0 0.1"/>
  </joint>
  <link name="lidar_link">
    <collision name="lidar_collision">
      <geometry>
        <box size="0.105 0.1 0.1"/>
      </geometry>
    </collision>
    <visual name="lidar_visual">
      <geometry>
        <mesh filename="package://lms1xx/meshes/sick-lms1xx.dae"/>
      </geometry>
    </visual>
  </link>
  <!-- ______________________________________________Front Suspension_______________________________________________ -->
  <!-- xxxxxxxxxxxxxxxxxxSTEERINGxxxxxxxxxxxxxxxxxxx-->
  <joint name="front_joint" type="revolute">
    <limit effort="100" lower="-0.785398163397" upper="0.785398163397" velocity="2"/>
    <dynamics damping="0.7"/>
    <axis xyz="0 0 1"/>
    <parent link="car_body"/>
    <child link="front_link"/>
    <origin xyz="0.6795 0.0 -0.29553"/>
  </joint>
  <link name="front_link">
    <inertial>
      <mass value="5"/>
      <origin rpy="0 0 0" xyz="0 0 0.127235"/>
      <inertia ixx="0.1" ixy="0.0" ixz="0.0" iyy="0.1" iyz="0.0" izz="0.1"/>
    </inertial>
    <visual>
      <origin rpy="0 0 0" xyz="0 0 -0.127235"/>
      <geometry>
        <box size="0.1 0.1 0.25447"/>
      </geometry>
      <material name="red"/>
    </visual>
    <collision>
      <origin rpy="0 0 0" xyz="0 0 0.127235"/>
      <geometry>
        <box size="0.1 0.1 0.25447"/>
      </geometry>
    </collision>
  </link>
  <joint name="front_axel_joint" type="continuous">
    <axis xyz="0 1 0"/>
    <dynamics damping="0.1"/>
    <parent link="front_link"/>
    <child link="front_axel_link"/>
    <origin rpy="0 0 0" xyz="0 0 -0.25447"/>
  </joint>
  <link name="front_axel_link">
    <inertial>
      <origin rpy="0 0 0" xyz="0 0 0"/>
      <mass value="5"/>
      <origin xyz="0 0 0"/>
      <inertia ixx="0.01" ixy="0.0" ixz="0.0" iyy="0.01" iyz="0.0" izz="0.01"/>
    </inertial>
    <visual>
      <origin rpy="0 0 0" xyz="0 0 0"/>
      <geometry>
        <box size="0.05 0.1 0.05"/>
      </geometry>
      <material name="green"/>
    </visual>
    <collision>
      <origin rpy="0 0 0" xyz="0 0 0"/>
      <geometry>
        <box size="0.05 0.1 0.05"/>
      </geometry>
    </collision>
  </link>
  <!--_____________________________________________Rear Suspension _______________________________________________________-->
  <joint name="rear_joint" type="fixed">
    <parent link="car_body"/>
    <child link="rear_link"/>
    <origin xyz="-0.6795 0.0 -0.29553"/>
  </joint>
  <link name="rear_link">
    <inertial>
      <mass value="5"/>
      <origin rpy="0 0 0" xyz="0 0 -0.05"/>
      <inertia ixx="0.1" ixy="0.0" ixz="0.0" iyy="0.1" iyz="0.0" izz="0.1"/>
    </inertial>
    <visual>
      <origin rpy="0 0 0" xyz="0 0 -0.127235"/>
      <geometry>
        <box size="0.1 0.1 0.25447"/>
      </geometry>
      <material name="red"/>
    </visual>
    <collision>
      <origin rpy="0 0 0" xyz="0 0 -0.127235"/>
      <geometry>
        <box size="0.1 0.1 0.25447"/>
      </geometry>
    </collision>
  </link>
  <!--xxxxxxxxxxxxxxxxxThrottlexxxxxxxxxxxxxxxxxxxxxxx-->
  <joint name="rear_axel_joint" type="continuous">
    <limit effort="100" velocity="5"/>
    <axis xyz="0 1 0"/>
    <dynamics damping="5"/>
    <parent link="rear_link"/>
    <child link="rear_axel_link"/>
    <origin rpy="0 0 0" xyz="0 0 -0.25447"/>
  </joint>
  <link name="rear_axel_link">
    <inertial>
      <origin rpy="0 0 0" xyz="0 0 0"/>
      <mass value="5"/>
      <inertia ixx="0.01" ixy="0.0" ixz="0.0" iyy="0.01" iyz="0.0" izz="0.01"/>
    </inertial>
    <visual>
      <origin rpy="0 0 0" xyz="0 0 0"/>
      <geometry>
        <box size="0.05 0.87684 0.05"/>
      </geometry>
      <material name="green"/>
    </visual>
    <collision>
      <origin rpy="0 0 0" xyz="0 0 0"/>
      <geometry>
        <box size="0.05 0.87684 0.05"/>
      </geometry>
    </collision>
  </link>
  <!--____________________________________Wheels________________________________________-->
  <!-- the front left wheel -->
  <joint name="front_left_wheel_joint" type="fixed">
    <parent link="front_axel_link"/>
    <child link="front_left_wheel_link"/>
    <origin rpy="0 0 0" xyz="0 -0.05 0"/>
  </joint>
  <link name="front_left_wheel_link">
    <inertial>
      <mass value="1"/>
      <origin rpy="1.57079632679 0 0" xyz="0 -0.02921 0"/>
      <inertia ixx="0.01" ixy="0.0" ixz="0.0" iyy="0.01" iyz="0.0" izz="0.01"/>
    </inertial>
    <visual>
      <origin rpy="1.57079632679 0 0" xyz="0 -0.02921 0"/>
      <geometry>
        <cylinder length="0.05842" radius="0.20447"/>
      </geometry>
      <material name="grey"/>
    </visual>
    <collision>
      <origin rpy="1.57079632679 0 0" xyz="0 -0.02921 0"/>
      <geometry>
        <cylinder length="0.05842" radius="0.20447"/>
      </geometry>
    </collision>
  </link>
  <!-- the front right wheel -->
  <joint name="front_right_wheel_joint" type="fixed">
    <parent link="front_axel_link"/>
    <child link="front_right_wheel_link"/>
    <origin rpy="0 0 0" xyz="0 0.05 0"/>
  </joint>
  <link name="front_right_wheel_link">
    <inertial>
      <mass value="1"/>
      <origin rpy="1.57079632679 0 0" xyz="0 0.02921 0"/>
      <inertia ixx="0.01" ixy="0.0" ixz="0.0" iyy="0.01" iyz="0.0" izz="0.01"/>
    </inertial>
    <visual>
      <origin rpy="1.57079632679 0 0" xyz="0 0.02921 0"/>
      <geometry>
        <cylinder length="0.05842" radius="0.20447"/>
      </geometry>
      <material name="grey"/>
    </visual>
    <collision>
      <origin rpy="1.57079632679 0 0" xyz="0 0.02921 0"/>
      <geometry>
        <cylinder length="0.05842" radius="0.20447"/>
      </geometry>
    </collision>
  </link>
  <!-- the back left wheel -->
  <joint name="rear_left_wheel_joint" type="fixed">
    <parent link="rear_axel_link"/>
    <child link="rear_left_wheel_link"/>
    <origin rpy="0 0 0" xyz="0 -0.43842 0"/>
  </joint>
  <link name="rear_left_wheel_link">
    <inertial>
      <mass value="1"/>
      <origin rpy="1.57079632679 0 0" xyz="0 -0.05842 0"/>
      <inertia ixx="0.01" ixy="0.0" ixz="0.0" iyy="0.01" iyz="0.0" izz="0.01"/>
    </inertial>
    <visual>
      <origin rpy="1.57079632679 0 0" xyz="0 -0.05842 0"/>
      <geometry>
        <cylinder length="0.11684" radius="0.20447"/>
      </geometry>
      <material name="grey"/>
    </visual>
    <collision>
      <origin rpy="1.57079632679 0 0" xyz="0 -0.05842 0"/>
      <geometry>
        <cylinder length="0.11684" radius="0.20447"/>
      </geometry>
    </collision>
  </link>
  <!-- the back right wheel -->
  <joint name="rear_right_wheel_joint" type="fixed">
    <parent link="rear_axel_link"/>
    <child link="rear_right_wheel_link"/>
    <origin rpy="0 0 0" xyz="0 0.43842 0"/>
  </joint>
  <link name="rear_right_wheel_link">
    <inertial>
      <mass value="2.5"/>
      <origin rpy="1.57079632679 0 0" xyz="0 0.05842 0"/>
      <inertia ixx="0.01" ixy="0.0" ixz="0.0" iyy="0.01" iyz="0.0" izz="0.01"/>
    </inertial>
    <visual>
      <origin rpy="1.57079632679 0 0" xyz="0 0.05842 0"/>
      <geometry>
        <cylinder length="0.11684" radius="0.20447"/>
      </geometry>
      <material name="grey"/>
    </visual>
    <collision>
      <origin rpy="1.57079632679 0 0" xyz="0 0.05842 0"/>
      <geometry>
        <cylinder length="0.11684" radius="0.20447"/>
      </geometry>
    </collision>
  </link>
  <!--________________________________________wheel_direction_bars_______________________________________________-->
  <!-- the back left wheel -->
  <joint name="left_spin_joint" type="fixed">
    <parent link="rear_left_wheel_link"/>
    <child link="left_spin_link"/>
    <origin rpy="0 0 0" xyz="0 -0.11684 0"/>
  </joint>
  <link name="left_spin_link">
    <visual>
      <origin rpy="0 0 0" xyz="0 0 0"/>
      <geometry>
        <box size="0.306705 0.01 0.05"/>
      </geometry>
      <material name="red"/>
    </visual>
    <collision>
      <origin rpy="0 0 0" xyz="0 0 0"/>
      <geometry>
        <box size="0.306705 0.01 0.05"/>
      </geometry>
    </collision>
  </link>
  <!-- the back right wheel -->
  <joint name="right_spin_joint" type="fixed">
    <parent link="rear_right_wheel_link"/>
    <child link="right_spin_link"/>
    <origin rpy="0 0 0" xyz="0 0.11684 0"/>
  </joint>
  <link name="right_spin_link">
    <visual>
      <origin rpy="0 0 0" xyz="0 0 0"/>
      <geometry>
        <box size="0.306705 0.01 0.05"/>
      </geometry>
      <material name="green"/>
    </visual>
    <collision>
      <origin rpy="0 0 0" xyz="0 0 0"/>
      <geometry>
        <box size="0.306705 0.01 0.05"/>
      </geometry>
    </collision>
  </link>
  <!--________________________________________control info_______________________________________________-->
  <transmission name="throttle">
    <type>transmission_interface/SimpleTransmission</type>
    <joint name="rear_axel_joint">
      <hardwareInterface>hardware_interface/EffortJointInterface</hardwareInterface>
    </joint>
    <actuator name="motor1">
      <hardwareInterface>hardware_interface/EffortJointInterface</hardwareInterface>
      <mechanicalReduction>1</mechanicalReduction>
    </actuator>
  </transmission>
  <transmission name="steering">
    <type>transmission_interface/SimpleTransmission</type>
    <joint name="front_joint">
      <hardwareInterface>hardware_interface/EffortJointInterface</hardwareInterface>
    </joint>
    <actuator name="motor2">
      <hardwareInterface>hardware_interface/EffortJointInterface</hardwareInterface>
      <mechanicalReduction>1</mechanicalReduction>
    </actuator>
  </transmission>
</robot>

